<?xml version="1.0" ?>
<!-- =================================================================================== -->
<!-- |    This document was autogenerated by xacro from rs013n.urdf.xacro              | -->
<!-- |    EDITING THIS FILE BY HAND IS NOT RECOMMENDED                                 | -->
<!-- =================================================================================== -->
<robot name="rs013n">
  <transmission name="$join1_trans">
    <type>transmission_interface/SimpleTransmission</type>
    <actuator name="joint1_motor">
      <hardwareInterface>hardware_interface/PositionJointInterface</hardwareInterface>
      <mechanicalReduction>1</mechanicalReduction>
    </actuator>
    <joint name="joint1">
      <hardwareInterface>hardware_interface/PositionJointInterface</hardwareInterface>
    </joint>
  </transmission>
  <transmission name="$join2_trans">
    <type>transmission_interface/SimpleTransmission</type>
    <actuator name="joint2_motor">
      <hardwareInterface>hardware_interface/PositionJointInterface</hardwareInterface>
      <mechanicalReduction>1</mechanicalReduction>
    </actuator>
    <joint name="joint2">
      <hardwareInterface>hardware_interface/PositionJointInterface</hardwareInterface>
    </joint>
  </transmission>
  <transmission name="$join3_trans">
    <type>transmission_interface/SimpleTransmission</type>
    <actuator name="joint3_motor">
      <hardwareInterface>hardware_interface/PositionJointInterface</hardwareInterface>
      <mechanicalReduction>1</mechanicalReduction>
    </actuator>
    <joint name="joint3">
      <hardwareInterface>hardware_interface/PositionJointInterface</hardwareInterface>
    </joint>
  </transmission>
  <transmission name="$join4_trans">
    <type>transmission_interface/SimpleTransmission</type>
    <actuator name="joint4_motor">
      <hardwareInterface>hardware_interface/PositionJointInterface</hardwareInterface>
      <mechanicalReduction>1</mechanicalReduction>
    </actuator>
    <joint name="joint4">
      <hardwareInterface>hardware_interface/PositionJointInterface</hardwareInterface>
    </joint>
  </transmission>
  <transmission name="$join5_trans">
    <type>transmission_interface/SimpleTransmission</type>
    <actuator name="joint5_motor">
      <hardwareInterface>hardware_interface/PositionJointInterface</hardwareInterface>
      <mechanicalReduction>1</mechanicalReduction>
    </actuator>
    <joint name="joint5">
      <hardwareInterface>hardware_interface/PositionJointInterface</hardwareInterface>
    </joint>
  </transmission>
  <transmission name="$join6_trans">
    <type>transmission_interface/SimpleTransmission</type>
    <actuator name="joint6_motor">
      <hardwareInterface>hardware_interface/PositionJointInterface</hardwareInterface>
      <mechanicalReduction>1</mechanicalReduction>
    </actuator>
    <joint name="joint6">
      <hardwareInterface>hardware_interface/PositionJointInterface</hardwareInterface>
    </joint>
  </transmission>
  <!-- link rviz colors -->
  <material name="_RS013NWhite">
    <color rgba="1 1 1 1"/>
  </material>
  <material name="_RS013NBlack">
    <color rgba="0 0 0 1"/>
  </material>
  <!-- rs013n start -->
  <!-- Link 0 -->
  <link name="_base_link">
    <visual>
      <geometry>
        <mesh filename="package://rs013n_description/meshes/RS013N_J0.stl"/>
      </geometry>
      <material name="_RS013NWhite"/>
      <origin rpy="0 0 0" xyz="0 0 0"/>
    </visual>
    <collision>
      <geometry>
        <mesh filename="package://rs013n_description/meshes/RS013N_J0.stl"/>
      </geometry>
      <material name="_RS013NWhite"/>
      <origin rpy="0 0 0" xyz="0 0 0"/>
    </collision>
    <inertial>
      <mass value="100.0"/>
      <inertia ixx="1.0" ixy="0.0" ixz="0.0" iyy="1.0" iyz="0.0" izz="1.0"/>
    </inertial>
  </link>
  <!-- Link 1 -->
  <joint name="_joint1" type="revolute">
    <axis rpy="0 0 0" xyz="0 0 -1"/>
    <limit effort="1000.0" lower="-3.141592653589793" upper="3.141592653589793" velocity="4.625122517784973"/>
    <origin rpy="0 0 0" xyz="0 0 0.505"/>
    <parent link="_base_link"/>
    <child link="_link1"/>
    <dynamics damping="0.0" friction="0.0"/>
  </joint>
  <link name="_link1">
    <visual>
      <geometry>
        <mesh filename="package://rs013n_description/meshes/RS013N_J1.stl"/>
      </geometry>
      <material name="_RS013NWhite"/>
      <origin rpy="0 0 0" xyz="0 0 0"/>
    </visual>
    <collision>
      <geometry>
        <mesh filename="package://rs013n_description/meshes/RS013N_J1.stl"/>
      </geometry>
      <material name="_RS013NWhite"/>
      <origin rpy="0 0 0" xyz="0 0 0"/>
    </collision>
    <inertial>
      <mass value="49.492"/>
      <inertia ixx="1.0" ixy="0.0" ixz="0.0" iyy="1.0" iyz="0.0" izz="1.0"/>
    </inertial>
  </link>
  <!-- Link 2 -->
  <joint name="_joint2" type="revolute">
    <axis rpy="0 0 0" xyz="0 0 1"/>
    <limit effort="1000.0" lower="-1.8325957145940461" upper="2.4085543677521746" velocity="4.363323129985824"/>
    <origin rpy="0 -1.5707963267948966 0" xyz="0 0 0.0"/>
    <parent link="_link1"/>
    <child link="_link2"/>
    <dynamics damping="0.0" friction="0.0"/>
  </joint>
  <link name="_link2">
    <visual>
      <geometry>
        <mesh filename="package://rs013n_description/meshes/RS013N_J2.stl"/>
      </geometry>
      <material name="_RS013NWhite"/>
      <origin rpy="0 1.5707963267948966 0" xyz="0 0 0"/>
    </visual>
    <collision>
      <geometry>
        <mesh filename="package://rs013n_description/meshes/RS013N_J2.stl"/>
      </geometry>
      <material name="_RS013NWhite"/>
      <origin rpy="0 1.5707963267948966 0" xyz="0 0 0"/>
    </collision>
    <inertial>
      <mass value="35.291"/>
      <inertia ixx="1.0" ixy="0.0" ixz="0.0" iyy="1.0" iyz="0.0" izz="1.0"/>
    </inertial>
  </link>
  <!-- Link 3 -->
  <joint name="_joint3" type="revolute">
    <axis rpy="0 0 0" xyz="0 0 -1"/>
    <limit effort="1000.0" lower="-2.775073510670984" upper="2.356194490192345" velocity="4.625122517784973"/>
    <origin rpy="0 0 0" xyz="0.7 0 0"/>
    <parent link="_link2"/>
    <child link="_link3"/>
    <dynamics damping="0.0" friction="0.0"/>
  </joint>
  <link name="_link3">
    <visual>
      <geometry>
        <mesh filename="package://rs013n_description/meshes/RS013N_J3.stl"/>
      </geometry>
      <material name="_RS013NWhite"/>
      <origin rpy="0 1.5707963267948966 0" xyz="0 0 0"/>
    </visual>
    <collision>
      <geometry>
        <mesh filename="package://rs013n_description/meshes/RS013N_J3.stl"/>
      </geometry>
      <material name="_RS013NWhite"/>
      <origin rpy="0 1.5707963267948966 0" xyz="0 0 0"/>
    </collision>
    <inertial>
      <mass value="15.457"/>
      <inertia ixx="1.0" ixy="0.0" ixz="0.0" iyy="1.0" iyz="0.0" izz="1.0"/>
    </inertial>
  </link>
  <!-- Link 4 -->
  <joint name="_joint4" type="revolute">
    <axis rpy="0 0 0" xyz="0 0 1"/>
    <limit effort="1000.0" lower="-3.490658503988659" upper="3.490658503988659" velocity="8.290313946973065"/>
    <origin rpy="0 1.5707963267948966 0" xyz="0.11 0 0"/>
    <parent link="_link3"/>
    <child link="_link4"/>
    <dynamics damping="0.0" friction="0.0"/>
  </joint>
  <link name="_link4">
    <visual>
      <geometry>
        <mesh filename="package://rs013n_description/meshes/RS013N_J4.stl"/>
      </geometry>
      <material name="_RS013NWhite"/>
      <origin rpy="0 0 0" xyz="0 0 0.65"/>
    </visual>
    <collision>
      <geometry>
        <mesh filename="package://rs013n_description/meshes/RS013N_J4.stl"/>
      </geometry>
      <material name="_RS013NWhite"/>
      <origin rpy="0 0 0" xyz="0 0 0.65"/>
    </collision>
    <inertial>
      <mass value="9.297"/>
      <inertia ixx="1.0" ixy="0.0" ixz="0.0" iyy="1.0" iyz="0.0" izz="1.0"/>
    </inertial>
  </link>
  <!-- Link 5 -->
  <joint name="_joint5" type="revolute">
    <axis rpy="0 0 0" xyz="0 0 -1"/>
    <limit effort="1000.0" lower="-2.181661564992912" upper="2.181661564992912" velocity="8.290313946973065"/>
    <origin rpy="0 -1.5707963267948966 0" xyz="0 0 0.65"/>
    <parent link="_link4"/>
    <child link="_link5"/>
    <dynamics damping="0.0" friction="0.0"/>
  </joint>
  <link name="_link5">
    <visual>
      <geometry>
        <mesh filename="package://rs013n_description/meshes/RS013N_J5.stl"/>
      </geometry>
      <material name="_RS013NWhite"/>
      <origin rpy="0 1.5707963267948966 0" xyz="0 0 0"/>
    </visual>
    <collision>
      <geometry>
        <mesh filename="package://rs013n_description/meshes/RS013N_J5.stl"/>
      </geometry>
      <material name="_RS013NWhite"/>
      <origin rpy="0 1.5707963267948966 0" xyz="0 0 0"/>
    </collision>
    <inertial>
      <mass value="1.792"/>
      <inertia ixx="1.0" ixy="0.0" ixz="0.0" iyy="1.0" iyz="0.0" izz="1.0"/>
    </inertial>
  </link>
  <!-- Link 6 -->
  <joint name="_joint6" type="revolute">
    <axis rpy="0 0 0" xyz="0 0 1"/>
    <limit effort="1000.0" lower="-6.283185307179586" upper="6.283185307179586" velocity="12.740903539558605"/>
    <origin rpy="0 1.5707963267948966 0" xyz="0.078 0 0"/>
    <parent link="_link5"/>
    <child link="_link6"/>
    <dynamics damping="0.0" friction="0.0"/>
  </joint>
  <link name="_link6">
    <visual>
      <geometry>
        <mesh filename="package://rs013n_description/meshes/RS013N_J6.stl"/>
      </geometry>
      <material name="_RS013NBlack"/>
      <origin rpy="0 0 0" xyz="0 0 0"/>
    </visual>
    <collision>
      <geometry>
        <mesh filename="package://rs013n_description/meshes/RS013N_J6.stl"/>
      </geometry>
      <material name="_RS013NBlack"/>
      <origin rpy="0 0 0" xyz="0 0 0"/>
    </collision>
    <inertial>
      <mass value="0.625"/>
      <inertia ixx="1.0" ixy="0.0" ixz="0.0" iyy="1.0" iyz="0.0" izz="1.0"/>
    </inertial>
  </link>
  <!-- Flange -->
  <joint name="_joint7" type="fixed">
    <origin rpy="0.0 0.0 0.0" xyz="0.0 0.0 0.0"/>
    <parent link="_link6"/>
    <child link="_flange"/>
  </joint>
  <link name="_flange">
    </link>
  <!-- Fix rs013n to world -->
  <link name="world"/>
  <joint name="world2base" type="fixed">
    <parent link="world"/>
    <child link="_base_link"/>
    <origin rpy="0 0 0" xyz="0 0 0"/>
  </joint>
</robot>
